Workbook

Sheet 간지
X3: 교량명 : | Z3: 갈전7교
D10: =Z3 -> 갈전7교

Sheet 간지(1)xx
A8: 내역서 적용수량

Sheet 내역서
D1: 규 격 | E1: 단위 | F1: =+간지!Z3 -> 갈전7교 | G1: 합 계 | H1: 비고
A2: 1. | B2: 구 조 물 공 | E2: 식
A3: =A2 -> 1. | B3: =IF(J3>9,CONCATENATE(J3,"."),CONCATENATE("0",J3,".")) -> 01. | C3: 토 공 | J3: =SUM($K$3:K3) -> 1 | K3: 1 | N3: =IF(K3="",IF(L3="","숨김","1"),"1") -> 1
B4: =IF(M4="",CONCATENATE(L4,"."),CONCATENATE(L4,"-",M4,".")) -> . | C4: 육상깎기 | J4: =SUM($K$3:K4) -> 1 | N4: =IF(K4="",IF(L4="","숨김","1"),"1") -> 숨김
B5: =IF(M5="",CONCATENATE(L5,"."),CONCATENATE(L5,"-",M5,".")) -> . | C5: 육상 토사 | E5: ㎥ | F5: =토공총괄집계표!H4 -> 0 | G5: =SUM(F5:F5) -> 0 | J5: =SUM($K$3:K5) -> 1 | N5: =IF(K5="",IF(L5="","숨김","1"),"1") -> 숨김
B6: =IF(M6="",CONCATENATE(L6,"."),CONCATENATE(L6,"-",M6,".")) -> . | C6: 구조물터파기 | J6: =SUM($K$3:K6) -> 1 | N6: =IF(K6="",IF(L6="","숨김","1"),"1") -> 숨김
B7: =IF(M7="",CONCATENATE(L7,"."),CONCATENATE(L7,"-",M7,".")) -> a. | C7: 육상 토사 | D7: 0∼4 m | E7: ㎥ | F7: =+토공총괄집계표!H7 -> 1748.131 | G7: =SUM(F7:F7) -> 1748.131 | J7: =SUM($K$3:K7) -> 1 | L7: a | N7: =IF(K7="",IF(L7="","숨김","1"),"1") -> 1
B8: =IF(M8="",CONCATENATE(L8,"."),CONCATENATE(L8,"-",M8,".")) -> . | C8: 육상 토사 | D8: 4m이상 | E8: ㎥ | F8: =+토공총괄집계표!H8 -> 0 | G8: =SUM(F8:F8) -> 0 | J8: =SUM($K$3:K8) -> 1 | N8: =IF(K8="",IF(L8="","숨김","1"),"1") -> 숨김
B9: =IF(M9="",CONCATENATE(L9,"."),CONCATENATE(L9,"-",M9,".")) -> . | C9: 육상 리핑암 | D9: 0∼4 m | E9: ㎥ | F9: =+토공총괄집계표!H9 -> 0 | G9: =SUM(F9:F9) -> 0 | J9: =SUM($K$3:K9) -> 1 | N9: =IF(K9="",IF(L9="","숨김","1"),"1") -> 숨김
B10: =IF(M10="",CONCATENATE(L10,"."),CONCATENATE(L10,"-",M10,".")) -> . | C10: 육상 리핑암 | D10: 4m이상 | E10: ㎥ | F10: =+토공총괄집계표!H10 -> 0 | G10: =SUM(F10:F10) -> 0 | J10: =SUM($K$3:K10) -> 1 | N10: =IF(K10="",IF(L10="","숨김","1"),"1") -> 숨김
B11: =IF(M11="",CONCATENATE(L11,"."),CONCATENATE(L11,"-",M11,".")) -> . | C11: 육상 발파암 | D11: 0∼4 m | E11: ㎥ | F11: =+토공총괄집계표!H11 -> 0 | G11: =SUM(F11:F11) -> 0 | J11: =SUM($K$3:K11) -> 1 | N11: =IF(K11="",IF(L11="","숨김","1"),"1") -> 숨김
B12: =IF(M12="",CONCATENATE(L12,"."),CONCATENATE(L12,"-",M12,".")) -> . | C12: 육상 발파암 | D12: 4m이상 | E12: ㎥ | F12: =+토공총괄집계표!H12 -> 0 | G12: =SUM(F12:F12) -> 0 | J12: =SUM($K$3:K12) -> 1 | N12: =IF(K12="",IF(L12="","숨김","1"),"1") -> 숨김
B13: =IF(M13="",CONCATENATE(L13,"."),CONCATENATE(L13,"-",M13,".")) -> b-1. | C13: 용수 토사 | D13: 0∼4 m | E13: ㎥ | F13: =+토공총괄집계표!H13 -> 3111.06 | G13: =SUM(F13:F13) -> 3111.06 | J13: =SUM($K$3:K13) -> 1 | L13: b | M13: 1 | N13: =IF(K13="",IF(L13="","숨김","1"),"1") -> 1
B14: =IF(M14="",CONCATENATE(L14,"."),CONCATENATE(L14,"-",M14,".")) -> b-2. | C14: 용수 토사 | D14: 4m이상 | E14: ㎥ | F14: =+토공총괄집계표!H14 -> 334.539 | G14: =SUM(F14:F14) -> 334.539 | J14: =SUM($K$3:K14) -> 1 | L14: b | M14: 2 | N14: =IF(K14="",IF(L14="","숨김","1"),"1") -> 1
B15: =IF(M15="",CONCATENATE(L15,"."),CONCATENATE(L15,"-",M15,".")) -> . | C15: 용수 리핑암 | D15: 0∼4 m | E15: ㎥ | G15: =SUM(F15:F15) -> 0 | J15: =SUM($K$3:K15) -> 1 | N15: =IF(K15="",IF(L15="","숨김","1"),"1") -> 숨김
B16: =IF(M16="",CONCATENATE(L16,"."),CONCATENATE(L16,"-",M16,".")) -> . | C16: 용수 리핑암 | D16: 4m이상 | E16: ㎥ | G16: =SUM(F16:F16) -> 0 | J16: =SUM($K$3:K16) -> 1 | N16: =IF(K16="",IF(L16="","숨김","1"),"1") -> 숨김
B17: =IF(M17="",CONCATENATE(L17,"."),CONCATENATE(L17,"-",M17,".")) -> . | C17: 용수 발파암 | D17: 0∼4 m | E17: ㎥ | F17: =토공총괄집계표!H15 -> 0 | G17: =SUM(F17:F17) -> 0 | J17: =SUM($K$3:K17) -> 1 | N17: =IF(K17="",IF(L17="","숨김","1"),"1") -> 숨김
B18: =IF(M18="",CONCATENATE(L18,"."),CONCATENATE(L18,"-",M18,".")) -> . | C18: 용수 발파암 | D18: 4m이상 | E18: ㎥ | F18: =토공총괄집계표!H16 -> 0 | G18: =SUM(F18:F18) -> 0 | J18: =SUM($K$3:K18) -> 1 | N18: =IF(K18="",IF(L18="","숨김","1"),"1") -> 숨김
B19: =IF(M19="",CONCATENATE(L19,"."),CONCATENATE(L19,"-",M19,".")) -> . | C19: 면정리 및 청소 | E19: ㎡ | F19: =+토공총괄집계표!H28 -> 0 | G19: =SUM(F19:F19) -> 0 | J19: =SUM($K$3:K19) -> 1 | N19: =IF(K19="",IF(L19="","숨김","1"),"1") -> 숨김
B20: =IF(M20="",CONCATENATE(L20,"."),CONCATENATE(L20,"-",M20,".")) -> c. | C20: 되메우기및다짐 | D20: 기계100% | E20: ㎥ | F20: =+토공총괄집계표!H17 -> 3818.185 | G20: =SUM(F20:F20) -> 3818.185 | J20: =SUM($K$3:K20) -> 1 | L20: c | N20: =IF(K20="",IF(L20="","숨김","1"),"1") -> 1
B21: =IF(M21="",CONCATENATE(L21,"."),CONCATENATE(L21,"-",M21,".")) -> d. | C21: 물푸기공 | E21: hr | F21: =토공총괄집계표!H29 -> 433.572 | G21: =SUM(F21:F21) -> 433.572 | J21: =SUM($K$3:K21) -> 1 | L21: d | N21: =IF(K21="",IF(L21="","숨김","1"),"1") -> 1
B22: =IF(M22="",CONCATENATE(L22,"."),CONCATENATE(L22,"-",M22,".")) -> . | C22: 면정리 및 청소 | E22: ㎡ | F22: =토공총괄집계표!H28 -> 0 | G22: =SUM(F22:F22) -> 0 | J22: =SUM($K$3:K22) -> 1 | N22: =IF(K22="",IF(L22="","숨김","1"),"1") -> 숨김
B23: =IF(M23="",CONCATENATE(L23,"."),CONCATENATE(L23,"-",M23,".")) -> . | C23: 피복석투하(해상수상) | D23: 0.1~0.4㎥ | E23: ㎥ | F23: =토공총괄집계표!H45 -> 0 | G23: =SUM(F23:F23) -> 0 | J23: =SUM($K$3:K23) -> 1 | N23: =IF(K23="",IF(L23="","숨김","1"),"1") -> 숨김
B24: =IF(M24="",CONCATENATE(L24,"."),CONCATENATE(L24,"-",M24,".")) -> . | C24: 피복석고르기(해상수상) | D24: 0.2㎥ 이하 | E24: ㎡ | F24: =F23 -> 0 | G24: =SUM(F24:F24) -> 0 | J24: =SUM($K$3:K24) -> 1 | N24: =IF(K24="",IF(L24="","숨김","1"),"1") -> 숨김
B25: =IF(M25="",CONCATENATE(L25,"."),CONCATENATE(L25,"-",M25,".")) -> . | C25: 거더 제작장 부설다짐 | D25: φ40, T=100mm | E25: ㎥ | F25: =토공총괄집계표!H51 -> 0 | G25: =SUM(F25:F25) -> 0 | J25: =SUM($K$3:K25) -> 1 | N25: =IF(K25="",IF(L25="","숨김","1"),"1") -> 숨김
B26: =IF(M26="",CONCATENATE(L26,"."),CONCATENATE(L26,"-",M26,".")) -> . | C26: 기초잡석채움 | E26: ㎥ | F26: =토공총괄집계표!H30 -> 0 | G26: =SUM(F26:F26) -> 0 | J26: =SUM($K$3:K26) -> 1 | N26: =IF(K26="",IF(L26="","숨김","1"),"1") -> 숨김
A27: =A75 -> 1. | B27: =IF(J27>9,CONCATENATE(J27,"."),CONCATENATE("0",J27,".")) -> 02. | C27: 지반개량공 | G27: =SUM(F27:F27) -> 0 | J27: =SUM($K$3:K27) -> 2 | K27: 1 | N27: =IF(K27="",IF(L27="","숨김","1"),"1") -> 1
B28: =IF(M28="",CONCATENATE(L28,"."),CONCATENATE(L28,"-",M28,".")) -> a. | C28: 심층혼합처리(개량공) | D28: N≤5/점성토/L=10.0M, 56공 (￠1,000×4rod, N<5) | E28: m | F28: 560 | G28: =SUM(F28:F28) -> 560 | J28: =SUM($K$3:K28) -> 2 | L28: a | N28: =IF(K28="",IF(L28="","숨김","1"),"1") -> 1
B29: =IF(M29="",CONCATENATE(L29,"."),CONCATENATE(L29,"-",M29,".")) -> b. | C29: 심층혼합처리(공삭공) | D29: N≤5/점성토/L=10.0M, 56공 | E29: m | F29: 112 | G29: =SUM(F29:F29) -> 112 | J29: =SUM($K$3:K29) -> 2 | L29: b | N29: =IF(K29="",IF(L29="","숨김","1"),"1") -> 1
B30: =IF(M30="",CONCATENATE(L30,"."),CONCATENATE(L30,"-",M30,".")) -> c. | C30: PILE DRIVER 및 PLANT 조립및해체 | D30: 외부반입/반출 | E30: 회 | F30: 28 | G30: =SUM(F30:F30) -> 28 | J30: =SUM($K$3:K30) -> 2 | L30: c | N30: =IF(K30="",IF(L30="","숨김","1"),"1") -> 1
B31: =IF(M31="",CONCATENATE(L31,"."),CONCATENATE(L31,"-",M31,".")) -> . | C31: 이토처리 | D31: B/H0.7㎥+D/T24ton | E31: ㎥ | G31: =SUM(F31:F31) -> 0 | J31: =SUM($K$3:K31) -> 2 | N31: =IF(K31="",IF(L31="","숨김","1"),"1") -> 숨김
A32: =A2 -> 1. | B32: =IF(J32>9,CONCATENATE(J32,"."),CONCATENATE("0",J32,".")) -> 03. | C32: 강관파일공 | J32: =SUM($K$3:K32) -> 3 | K32: 1 | N32: =IF(K32="",IF(L32="","숨김","1"),"1") -> 1
B33: =IF(M33="",CONCATENATE(L33,"."),CONCATENATE(L33,"-",M33,".")) -> a-1. | C33: 강관파일 | D33: Φ508.0M/M, T=12mm | J33: =SUM($K$3:K33) -> 3 | L33: a | M33: 1 | N33: =IF(K33="",IF(L33="","숨김","1"),"1") -> 1
B34: =IF(M34="",CONCATENATE(L34,"."),CONCATENATE(L34,"-",M34,".")) -> a-2. | C34: 강관파일 자재비 | E34: m | F34: =구조물공총괄집계표!G131 -> 5021.52 | G34: =SUM(F34:F34) -> 5021.52 | J34: =SUM($K$3:K34) -> 3 | L34: a | M34: 2 | N34: =IF(K34="",IF(L34="","숨김","1"),"1") -> 1
B35: =IF(M35="",CONCATENATE(L35,"."),CONCATENATE(L35,"-",M35,".")) -> a-3. | C35: 천공 후 항타 | E35: m | F35: =구조물공총괄집계표!G132+구조물공총괄집계표!G133+구조물공총괄집계표!G134 -> 4740.9 | G35: =SUM(F35:F35) -> 4740.9 | J35: =SUM($K$3:K35) -> 3 | L35: a | M35: 3 | N35: =IF(K35="",IF(L35="","숨김","1"),"1") -> 1
B36: =IF(M36="",CONCATENATE(L36,"."),CONCATENATE(L36,"-",M36,".")) -> a-4. | C36: 두부및선단보강 | E36: 본 | F36: =구조물공총괄집계표!G137 -> 208 | G36: =SUM(F36:F36) -> 208 | J36: =SUM($K$3:K36) -> 3 | L36: a | M36: 4 | N36: =IF(K36="",IF(L36="","숨김","1"),"1") -> 1
B37: =IF(M37="",CONCATENATE(L37,"."),CONCATENATE(L37,"-",M37,".")) -> a-5. | C37: 강관파일이음 | E37: 본 | F37: =구조물공총괄집계표!G138 -> 208 | G37: =SUM(F37:F37) -> 208 | J37: =SUM($K$3:K37) -> 3 | L37: a | M37: 5 | N37: =IF(K37="",IF(L37="","숨김","1"),"1") -> 1
B38: =IF(M38="",CONCATENATE(L38,"."),CONCATENATE(L38,"-",M38,".")) -> . | C38: 시멘트밀크 | E38: ㎥ | F38: =구조물공총괄집계표!G135+구조물공총괄집계표!G136 -> 964.833 | G38: =SUM(F38:F38) -> 964.833 | J38: =SUM($K$3:K38) -> 3 | N38: =IF(K38="",IF(L38="","숨김","1"),"1") -> 숨김
B39: =IF(M39="",CONCATENATE(L39,"."),CONCATENATE(L39,"-",M39,".")) -> . | C39: 장비조립 및 해체 | D39: 천공, 항타 | E39: 회 | G39: =SUM(F39:F39) -> 0 | J39: =SUM($K$3:K39) -> 3 | N39: =IF(K39="",IF(L39="","숨김","1"),"1") -> 숨김
B40: =IF(M40="",CONCATENATE(L40,"."),CONCATENATE(L40,"-",M40,".")) -> . | C40: 강관파일 | D40: Φ609.0M/M, T=12mm | J40: =SUM($K$3:K40) -> 3 | N40: =IF(K40="",IF(L40="","숨김","1"),"1") -> 숨김
...

Sheet 간지(2)xx
A8: 주요자재 집계표

Sheet 주요자재
A1: ="< "&간지!$Z$3&" >" -> < 갈전7교 >
A2: 자 재 명 | B2: 규 격 | D2: 단 위 | E2: 수 량 | F2: 비 고
A3: 철 근 | C3: D10 | D3: ton | E3: =철근총괄!K64 -> 0 | F3: 할증
C4: D13 | D4: ton | E4: =철근총괄!J64 -> 0 | F4: "
B5: 연 | C5: D16 | D5: ton | E5: =철근총괄!I64 -> 0 | F5: "
C6: D19 | D6: ton | E6: =철근총괄!H64 -> 0 | F6: "
B7: 강 | C7: D22 | D7: ton | E7: =철근총괄!G64 -> 0 | F7: "
C8: D25 | D8: ton | E8: =철근총괄!F64 -> 0 | F8: "
C9: D29 | D9: ton | E9: =철근총괄!E64 -> 0 | F9: "
C10: D32 | D10: ton | E10: =철근총괄!D64 -> 0 | F10: "
B11: 소 계 | D11: ton | E11: =SUM(E3:E10) -> 0 | G11: =+철근총괄!L64 -> 0 | H11: =+E11-G11 -> 0
C12: H10 | D12: ton | E12: =철근총괄!K33 -> 0 | F12: 할증
C13: H13 | D13: ton | E13: =철근총괄!J33 -> 5.846 | F13: "
C14: H16 | D14: ton | E14: =철근총괄!I33 -> 31.812 | F14: "
B15: 고 | C15: H19 | D15: ton | E15: =철근총괄!H33 -> 21.031 | F15: "
C16: H22 | D16: ton | E16: =철근총괄!G33 -> 54.361 | F16: "
B17: 강 | C17: H25 | D17: ton | E17: =철근총괄!F33 -> 64.601 | F17: "
C18: H29 | D18: ton | E18: =철근총괄!E33 -> 0 | F18: "
C19: H32 | D19: ton | E19: =철근총괄!D33 -> 0 | F19: "
B20: 소 계 | D20: ton | E20: =SUM(E12:E19) -> 177.651 | G20: =+철근총괄!L33 -> 177.651 | H20: =+G20-E20 -> 0
B21: 철 근 계 | D21: ton | E21: =SUM(E20,E11) -> 177.651
B22: 고 철 | D22: Kg | E22: =ROUND((E21-철근총괄!L32-철근총괄!L63),3)*1000 -> 8444
A23: 레 미 콘 | B23: =내역서!D470 -> 25-35-150 | D23: M³ | E23: =ROUNDUP(콘크리트자재집계!G13*1.01,0) -> 973 | F23: 1% 할증
B24: =내역서!D471 -> 25-27-150 | D24: M³ | E24: =ROUNDUP(콘크리트자재집계!H13*1.01,0) -> 470 | F24: "
B25: =내역서!D472 -> 25-35-80 | D25: M³ | E25: =ROUNDUP(콘크리트자재집계!I13*1.01,0) -> 0
B26: =내역서!D473 -> 25-24-150 | D26: M³ | E26: =ROUNDUP(콘크리트자재집계!O13*1.01,0) -> 0
B27: =내역서!D474 -> 25-18-150 | D27: M³ | E27: =ROUNDUP(콘크리트자재집계!C13*1.02,0) -> 83 | F27: 2% 할증
B28: =내역서!D476 -> 25-16-150 | D28: M³ | E28: =ROUNDUP(콘크리트자재집계!E13*1.02,0) -> 0
A29: 시멘트 | B29: (40KG) | D29: 포대 | E29: =ROUNDUP('시멘트 및 골재량 산출'!E19*1.02,0) -> 35327 | F29: 2% 할증
A30: 모래 | D30: M³ | E30: ='골재수량 집계표'!D12*1.06 -> 0 | F30: 6% 할증
A31: 자갈 | B31: Φ13M/M | D31: M³ | E31: ='골재수량 집계표'!E12*1.04 -> 0 | F31: 4% 할증
B32: Φ19M/M | D32: M³ | E32: ='골재수량 집계표'!F12*1.04 -> 0 | F32: "
B33: Φ25M/M | D33: M³ | E33: ='골재수량 집계표'!G12*1.04 -> 0 | F33: "
A34: 세굴방지사석 | B34: Φ310mm | D34: M³ | E34: ='골재수량 집계표'!K12*1.1 -> 0 | F34: 10% 할증
A35: 제작장 잡석 | B35: Φ40, T=100mm | D35: M³ | E35: =토공총괄집계표!H51*1.04 -> 0 | F35: 4% 할증
A36: 기초잡석 | B36: 깬잡석 | D36: M³ | E36: ='골재수량 집계표'!L12 -> 0 | F36: 4% 할증
A37: 난 간 | B37: 보도용 난간 | D37: m | E37: =구조물공총괄집계표!G94 -> 0
B38: 차량용 방호울타리 | D38: m | E38: =구조물공총괄집계표!G93 -> 35.704
A39: 팽창제 | B39: 1m3당 155 kg | D39: ton | E39: =내역서!G441 -> 0
A40: 뒷채움 | B40: SB-1 | D40: M³ | E40: =토공총괄집계표!H26*1.04 -> 1247.9012 | F40: 4% 할증 | H40: ='골재수량 집계표'!J12 -> 1543.4567
...

Sheet 콘크리트자재집계
A1: ="< "&간지!$Z$3&" >" -> < 갈전7교 >
C2: 무근 | G2: 육상펌프카
A3: 구 분 | B3: 단위 | C3: 25-18-150 | F3: 0-15.0 m | G3: 25-35-150 | H3: 25-27-150 | I3: 25-35-80 | M3: 15.0 m 이상 | O3: 25-24-150 | P3: 비 고
F4: 19-27-15 | M4: 25-35-150 | N4: 25-30-150
A5: =간지!$Z$3 -> 갈전7교 | B5: ㎥ | C5: =구조물공총괄집계표!E8 -> 81.368 | D5: =구조물공총괄집계표!#REF! -> #REF! | E5: =구조물공총괄집계표!E9 -> 0 | F5: =구조물공총괄집계표!E3 -> 0 | G5: =구조물공총괄집계표!E4 -> 963.067 | H5: =구조물공총괄집계표!E5 -> 464.94 | I5: =구조물공총괄집계표!E6 -> 0 | O5: =구조물공총괄집계표!E7 -> 0
B6: ㎥ | C6: =구조물공총괄집계표!F8 -> 0 | D6: =구조물공총괄집계표!#REF! -> #REF! | I6: =구조물공총괄집계표!F6 -> 0 | O6: =구조물공총괄집계표!F7 -> 0
B7: ㎥
B8: ㎥
B9: ㎥
B10: ㎥
B11: ㎥
A13: 소 계 | B13: ㎥ | C13: =SUM(C5:C12) -> 81.368 | D13: =SUM(D5:D12) -> #REF! | E13: =SUM(E5:E12) -> 0 | F13: =SUM(F5:F12) -> 0 | G13: =SUM(G5:G12) -> 963.067 | H13: =SUM(H5:H12) -> 464.94 | I13: =SUM(I5:I12) -> 0 | J13: =SUM(J5:J12) -> 0 | K13: =SUM(K5:K12) -> 0 | M13: =SUM(M5:M12) -> 0 | N13: =SUM(N5:N12) -> 0 | O13: =SUM(O5:O12) -> 0
A14: 총 계 | B14: ㎥ | C14: =C13 -> 81.368 | G14: =SUM(F13:O13) -> 1428.007
C16: =+C14+G14 -> 1509.375

Sheet 골재수량 집계표
A1: 구조물공 골재수량 집계표
A2: ="< "&간지!$Z$3&" >" -> < 갈전7교 > | M2: (단위중량 - 모래 : 1.6 t/m³, 자갈 : 1.7 t/m³)
D4: 세골재 | J4: 뒷 채 움 | K4: 사 석 | L4: 깬 잡 석 | M4: 비 고
D5: (M³) | E5: Φ13M/M | F5: Φ19M/M | G5: Φ25M/M | H5: Φ32M/M | I5: Φ40M/M | J5: SB-1 | K5: Φ300
B6: 콘 크 리 트 용
B7: 말 뚝 속 채 움 모 래
B8: 세굴 방지용 사석 채움
B9: 교 대 뒷 채 움 | J9: =토공총괄집계표!H26*1.175/0.95 -> 1484.093 | M9: 토량환산계수 적용 (L/C)
B10: 돌 망 태 용 깬 잡 석 | M10: 현장암유용
B11: 기 초 잡 석 채 움 | L11: =토공총괄집계표!H30 -> 0
A12: 계 | B12: M³ | D12: =SUM(D6:D11) -> 0 | E12: =SUM(E6:E11)*1.04 -> 0 | F12: =SUM(F6:F11)*1.04 -> 0 | G12: =SUM(G6:G11) -> 0 | H12: =SUM(H6:H11)*1.04 -> 0 | I12: =SUM(I6:I11)*1.04 -> 0 | J12: =SUM(J6:J11)*1.04 -> 1543.4567 | K12: =SUM(K6:K11) -> 0 | L12: =SUM(L6:L11)*1.04 -> 0 | N12: ---> 표준품셈에서 모르타르 재료할증은 포함있으므로 할증안함

Sheet 시멘트 및 골재량 산출
A1: ="< "&간지!$Z$3&" >" -> < 갈전7교 >
C2: 수 량 | D2: 시 멘 트 | F2: 세 골 재 | H2: 조 골 재
A3: 공 | B3: 종 | C3: (㎥) | H3: φ13 | J3: φ19 | L3: φ25 | N3: φ40
D4: TON/㎥ | E4: TON | F4: TON/㎥ | G4: TON | H4: TON/㎥ | I4: TON | J4: TON/㎥ | K4: TON | L4: TON/㎥ | M4: TON | N4: TON/㎥ | O4: TON
A5: 무수축 | B5: 상부공 | D5: 0.777 | E5: =ROUND(C5*D5,3) -> 0 | G5: =ROUND(C5*F5,3) -> 0
A6: 몰탈 | B6: 하부공 | D6: 0.777 | E6: =ROUND(C6*D6,3) -> 0 | G6: =ROUND(C6*F6,3) -> 0
A7: (1:1) | D7: 0.777 | E7: =ROUND(C7*D7,3) -> 0 | G7: =ROUND(C7*F7,3) -> 0
A8: 무수축콘크리트 | C8: =구조물공총괄집계표!G59 -> 0 | E8: =ROUND(C8*D8,3) -> 0 | G8: =ROUND(C8*F8,3) -> 0
A9: 무수축몰탈(1:3) | D9: 0.51 | E9: =ROUND(C9*D9,3) -> 0 | G9: =ROUND(C9*F9,3) -> 0
A10: 그라우팅 밀크 | B10: BEAM | D10: 1.301 | E10: =ROUND(C10*D10,3) -> 0 | G10: =ROUND(C10*F10,3) -> 0
B11: 선단보강 | C11: =구조물공총괄집계표!G135 -> 126.474 | D11: 1.09 | E11: =ROUND(C11*D11,3) -> 137.857 | G11: =ROUND(C11*F11,3) -> 0
B12: 주면보강 | C12: =구조물공총괄집계표!G136 -> 838.359 | D12: 0.983 | E12: =ROUND(C12*D12,3) -> 824.107 | G12: =ROUND(C12*F12,3) -> 0
A13: EARTH ANCHOR 그라우팅 | C13: =구조물공총괄집계표!G214 -> 0 | D13: 1.303 | E13: =C13*D13 -> 0 | G13: =ROUND(C13*F13,3) -> 0
A14: 심층혼합공법 | C14: 1693.44 | D14: 0.25 | E14: 423.36
A15: 소 계 | C15: =SUM(C5:C14) -> 2658.273 | E15: =SUM(E5:E14) -> 1385.324 | G15: =SUM(G5:G13) -> 0 | I15: =SUM(I5:I13) -> 0 | K15: =SUM(K5:K13) -> 0 | M15: =SUM(M5:M13) -> 0 | O15: =SUM(O5:O13) -> 0
A16: 계 | C16: 시멘트 분말(TON) | E16: =ROUND(E15,3) -> 1385.324 | G16: =SUM(G15) -> 0 | I16: =SUM(I15) -> 0 | K16: =SUM(K15,) -> 0 | M16: =SUM(M15,) -> 0 | O16: =SUM(O15,) -> 0
D18: ="* 시멘트 : "&FIXED($E$16*1000,0)&" ÷ 40 =" -> * 시멘트 : 1,385,324 ÷ 40 = | E18: =" "&FIXED(ROUNDUP($E$16*1000/40,0),0)&" 포대" -> 34,634 포대
E19: =ROUNDUP(E16*1000/40,0) -> 34634
E22: =E16/40 -> 34.6331

Sheet 간지(3)xx
A8: 이월수량 집계표

Sheet 전체이월수량
A1: 공 종 | B1: 규 격 | C1: 단위 | D1: 토공 | E1: 포장공 | F1: 계 | G1: 비고
A3: 유용토 (육상) | B3: 토사 | C3: m³ | D3: =토공총괄집계표!H18+토공총괄집계표!H54 -> 1414.045 | F3: =SUM(D3:E3) -> 1414.045
B4: 리핑암 | C4: m³ | F4: =SUM(D4:E4) -> 0
B5: 발파암 | C5: m³ | F5: =SUM(D5:E5) -> 0
A6: 유용토 (용수) | B6: 토사 | C6: m³ | D6: =토공총괄집계표!H21 -> 0 | F6: =SUM(D6:E6) -> 0
B7: 리핑암 | C7: m³ | D7: =토공총괄집계표!H22 -> 0 | F7: =SUM(D7:E7) -> 0
B8: 발파암 | C8: m³ | D8: =토공총괄집계표!H23 -> 0 | F8: =SUM(D8:E8) -> 0
B9: 사석 | C9: m³ | F9: =SUM(D9:E9) -> 0
A10: 부족토 | B10: 되메우기토사 | C10: m³ | D10: =토공총괄집계표!H25 -> 0 | F10: =SUM(D10:E10) -> 0
A11: 공제토 | B11: 노상 | C11: m³ | D11: =토공총괄집계표!H34 -> 486.583 | F11: =SUM(D11:E11) -> 486.583
B12: 노체 | C12: m³ | D12: =토공총괄집계표!H35 -> 291.058 | F12: =SUM(D12:E12) -> 291.058
A13: 가도 축도 | B13: 흙쌓기 및 철거 | C13: m³ | F13: =SUM(D13:E13) -> 0
B14: 마대쌓기 및 철거 | C14: ea | F14: =SUM(D14:E14) -> 0
B15: 오탁방지막 | C15: m | F15: =SUM(D15:E15) -> 0
B16: 가배수관(Φ1000mm) | C16: m | F16: =SUM(D16:E16) -> 0
B17: 본선 유용 (80%) | C17: m³ | F17: =SUM(D17:E17) -> 0
A18: 앞성토 | C18: m³ | F18: =SUM(D18:E18) -> 0
A19: 뒷채움 | B19: SB-1 | C19: m³ | F19: =SUM(D19:E19) -> 0
A20: 줄떼 | B20: 추가 | C20: ㎡ | F20: =SUM(D20:E20) -> 0
B21: 공제 | C21: ㎡ | F21: =SUM(D21:E21) -> 0
A22: 교면포장 | B22: 보도용 칼라콘크리트 | C22: ㎡ | E22: =구조물공총괄집계표!G65 -> 0 | F22: =SUM(D22:E22) -> 0
B23: 아스콘 포장 | C23: ㎡ | F23: =SUM(D23:E23) -> 0
A24: 콘크리트 깨기 | B24: 무근콘크리트 | C24: m³ | D24: =토공총괄집계표!H47 -> 0 | F24: =SUM(D24:E24) -> 0
B25: 폐아스콘 | C25: m³ | D25: =토공총괄집계표!H48 -> 0 | F25: =SUM(D25:E25) -> 0
A26: 페기물 처리 | B26: 철근 콘크리트 | C26: ton | D26: 3493.641 | F26: =SUM(D26:E26) -> 3493.641
B27: 폐아스콘 | C27: ton | D27: =토공총괄집계표!H50 -> 0 | F27: =SUM(D27:E27) -> 0
A28: 원지반토 | B28: 사 토 | C28: m³ | F28: =SUM(D28:E28) -> 0
A29: 제작장 잡석 | B29: Φ40, T=100mm | C29: m³ | F29: =SUM(D29:E29) -> 0
A30: 세굴방지사석 | C30: m³ | D30: =토공총괄집계표!H31 -> 0 | F30: =SUM(D30:E30) -> 0
A31: 폐기물 운반 | B31: 폐콘크리트 | C31: m³ | D31: =344.27+1163.353 -> 1507.623 | F31: =SUM(D31:E31) -> 1507.623

Sheet 간지(4)xx
A8: 총괄수량 집계표

Sheet 토공총괄집계표
I1: ="< "&간지!$Z$3&" >" -> < 갈전7교 >
A2: 공종 | B2: 규격 | D2: 단위 | E2: 갈전7교 | F2: 가축도 | G2: 옹벽 | H2: 계 | I2: 비고
A4: 육상깎기 | B4: 토 사 | D4: ㎥ | H4: =SUM(E4:G4) -> 0
B5: 리핑암 | D5: ㎥ | H5: =SUM(E5:G5) -> 0
B6: 발파암 | D6: ㎥ | H6: =SUM(E6:G6) -> 0
A7: 터파기 | B7: 육상토사 | C7: 0~4m | D7: ㎥ | E7: ='[132]토공수량 토공 집계표'!$G$3 -> 1748.131 | H7: =SUM(E7:G7) -> 1748.131
B8: 육상토사 | C8: 4m이상 | D8: ㎥ | H8: =SUM(E8:G8) -> 0
B9: 육상리핑암 | C9: 0~4m | D9: ㎥ | H9: =SUM(E9:G9) -> 0
B10: 육상리핑암 | C10: 4m이상 | D10: ㎥ | H10: =SUM(E10:G10) -> 0
B11: 육상발파암 | C11: 0~4m | D11: ㎥ | H11: =SUM(E11:G11) -> 0
B12: 육상발파암 | C12: 4m이상 | D12: ㎥ | H12: =SUM(E12:G12) -> 0
B13: 용수토사 | C13: 0~4m | D13: ㎥ | E13: ='[132]토공수량 토공 집계표'!$G$4 -> 3111.06 | H13: =SUM(E13:G13) -> 3111.06
B14: 용수토사 | C14: 4m이상 | D14: ㎥ | E14: ='[132]토공수량 토공 집계표'!$G$5 -> 334.539 | H14: =SUM(E14:G14) -> 334.539
B15: 용수발파암 | C15: 0~4m | D15: ㎥ | H15: =SUM(E15:G15) -> 0
B16: 용수발파암 | C16: 4m이상 | D16: ㎥ | H16: =SUM(E16:G16) -> 0
A17: 되메우기 | B17: 기계다짐 | C17: 토사 | D17: ㎥ | E17: ='[132]토공수량 토공 집계표'!$G$8 -> 3818.185 | H17: =SUM(E17:G17) -> 3818.185
A18: 유용토 (육상) | B18: 토사 | D18: ㎥ | E18: ='[132]토공수량 토공 집계표'!$G$9 -> 1375.545 | H18: =SUM(E18:G18) -> 1375.545 | I18: 타공정이월 | J18: 도로
B19: 리핑암 | D19: ㎥ | H19: =SUM(E19:G19) -> 0 | I19: 타공정이월 | J19: 도로
B20: 발파암 | D20: ㎥ | H20: =SUM(E20:G20) -> 0 | I20: 타공정이월 | J20: 도로
A21: 유용토 (용수) | B21: 토사 | D21: ㎥ | H21: =SUM(E21:G21) -> 0
B22: 리핑암 | D22: ㎥ | H22: =SUM(E22:G22) -> 0
B23: 발파암 | D23: ㎥ | H23: =SUM(E23:G23) -> 0
B24: 사석(방조제피복석) | D24: ㎥ | H24: =SUM(E24:G24) -> 0
A25: 부족토 | B25: 되메우기토사 | D25: ㎥ | H25: =SUM(E25:G25) -> 0
A26: 뒷채움 | B26: SB-1 | D26: ㎥ | E26: ='[132]토공수량 토공 집계표'!$G$7 -> 1199.905 | H26: =SUM(E26:G26) -> 1199.905
A27: 원지반토 | B27: 사토 | D27: ㎥ | H27: =SUM(E27:G27) -> 0
A28: 면고르기 | D28: ㎡ | H28: =SUM(E28:G28) -> 0
A29: 물푸기 | D29: hr | E29: ='[132]토공수량 토공 집계표'!$G$6 -> 433.572 | H29: =SUM(E29:G29) -> 433.572
A30: 기초잡석채움 | D30: ㎥ | H30: =SUM(E30:G30) -> 0
A31: 세굴방지 사석채움 | B31: 사석 부설 | D31: ㎥ | H31: =SUM(E31:G31) -> 0
B32: 능형망 | D32: ㎡ | H32: =SUM(E32:G32) -> 0
B33: 쇄석 하상골재 | D33: ㎡ | H33: =SUM(E33:G33) -> 0
A34: 공제토 | B34: 노상공제 | D34: ㎥ | E34: ='[132]토공수량 토공 집계표'!$G$10 -> 486.583 | H34: =SUM(E34:G34) -> 486.583 | I34: 타공정이월
B35: 노체공제 | D35: ㎥ | E35: ='[132]토공수량 토공 집계표'!$G$11 -> 291.058 | H35: =SUM(E35:G35) -> 291.058 | I35: 타공정이월
A36: 앞성토 | D36: ㎥ | H36: =SUM(E36:G36) -> 0
A37: 줄떼공제 | D37: ㎥ | H37: =SUM(E37:G37) -> 0
A38: 줄떼추가 | D38: ㎥ | H38: =SUM(E38:G38) -> 0
A39: 보호블럭 | D39: ㎡ | H39: =SUM(E39:G39) -> 0
A40: 보호블럭기초 | D40: m | H40: =SUM(E40:G40) -> 0
A41: 보호블럭마감 | D41: m | H41: =SUM(E41:G41) -> 0
...

Sheet 구조물공총괄집계표
H1: ="< "&간지!$Z$3&" >" -> < 갈전7교 >
A2: 공종 | B2: 규격 | D2: 단위 | E2: 갈전7교 | F2: 옹벽 | G2: 총계 | H2: 비고
A3: 철근콘크리트 | B3: =내역서!D469 -> 19-27-15 | D3: ㎥ | G3: =SUM(E3:F3) -> 0
B4: =내역서!D470 -> 25-35-150 | D4: ㎥ | E4: ='[131]갈전7교 교량 일반수량 집계표'!$I$4:$I$5 -> 963.067 | G4: =SUM(E4:F4) -> 963.067
B5: =내역서!D471 -> 25-27-150 | D5: ㎥ | E5: ='[131]갈전7교 교량 일반수량 집계표'!$H$3 -> 464.94 | G5: =SUM(E5:F5) -> 464.94
B6: =내역서!D472 -> 25-35-80 | D6: ㎥ | G6: =SUM(E6:F6) -> 0
B7: =내역서!D473 -> 25-24-150 | D7: ㎥ | G7: =SUM(E7:F7) -> 0
A8: 무근콘크리트 | B8: =내역서!D474 -> 25-18-150 | D8: ㎥ | E8: ='[131]갈전7교 교량 일반수량 집계표'!$H$6 -> 81.368 | G8: =SUM(E8:F8) -> 81.368
B9: =내역서!D476 -> 25-16-150 | D9: ㎥ | G9: =SUM(E9:F9) -> 0
A10: 콘크리트타설 | B10: 철근 | C10: H=0.0~15.0m | D10: ㎥ | E10: =SUM(E3:E7) -> 1428.007 | F10: =SUM(F3:F7) -> 0 | G10: =SUM(E10:F10) -> 1428.007
B11: 무근 | C11: VIB제외 | D11: ㎥ | E11: =E8 -> 81.368 | F11: =F8 -> 0 | G11: =SUM(E11:F11) -> 81.368
C12: VIB포함 | D12: ㎥ | G12: =SUM(E12:F12) -> 0
A13: 거푸집 | B13: 합판3회 | C13: 수직면(H=0~7m) | D13: ㎡ | G13: =SUM(E13:F13) -> 0
C14: 수직면(H=7~10m) | D14: ㎡ | G14: =SUM(E14:F14) -> 0
C15: 수직면(H=10~13m) | D15: ㎡ | G15: =SUM(E15:F15) -> 0
C16: 수직면(H=13~16m) | D16: ㎡ | G16: =SUM(E16:F16) -> 0
C17: 경사면(H=0~7m) | D17: ㎡ | G17: =SUM(E17:F17) -> 0
C18: 수평면(H=0~7m) | D18: ㎡ | G18: =SUM(E18:F18) -> 0
B19: 합판3회 | C19: H=0~7m | D19: ㎡ | E19: ='[131]갈전7교 교량 일반수량 집계표'!$I$11 -> 1492.629 | G19: =SUM(E19:F19) -> 1492.629
B20: 합판4회 | C20: H=0~7m | D20: ㎡ | E20: ='[131]갈전7교 교량 일반수량 집계표'!$H$10 -> 38.465 | G20: =SUM(E20:F20) -> 38.465
B21: 합판6회 | C21: H=0~7m | D21: ㎡ | E21: ='[131]갈전7교 교량 일반수량 집계표'!$H$9 -> 28.209 | G21: =SUM(E21:F21) -> 28.209
B22: 무늬 | C22: H=0~7m | D22: ㎡ | G22: =SUM(E22:F22) -> 0
C23: H=7~10m | D23: ㎡ | G23: =SUM(E23:F23) -> 0
C24: H=10~13m | D24: ㎡ | G24: =SUM(E24:F24) -> 0
B25: 강재 | C25: H=0~7m | D25: ㎡ | G25: =SUM(E25:F25) -> 0
C26: H=7~10m | D26: ㎡ | G26: =SUM(E26:F26) -> 0
C27: H=10~13m | D27: ㎡ | G27: =SUM(E27:F27) -> 0
B28: 강재원형 | C28: H=0~7m | D28: ㎡ | G28: =SUM(E28:F28) -> 0
C29: H=7~10m | D29: ㎡ | G29: =SUM(E29:F29) -> 0
C30: H=10~13m | D30: ㎡ | G30: =SUM(E30:F30) -> 0
B31: 유로폼(보통) | C31: H=0~7m | D31: ㎡ | G31: =SUM(E31:F31) -> 0
B32: 유로폼(복잡) | C32: H=0~7m | D32: ㎡ | G32: =SUM(E32:F32) -> 0
B33: 유로폼(복잡) | C33: H=7~10m | D33: ㎡ | G33: =SUM(E33:F33) -> 0
A34: 동바리 | B34: 잡철물동바리 | D34: EA | G34: =SUM(E34:F34) -> 0
B35: 데크피니샤용 강재 | D35: ㎡ | G35: =SUM(E35:F35) -> 0
B36: 목재동바리(4회) | D36: 공/㎥ | G36: =SUM(E36:F36) -> 0
B37: 시스템동바리 | D37: 공/㎥ | E37: ='[131]갈전7교 교량 일반수량 집계표'!$H$15 -> 2245.057 | G37: =SUM(E37:F37) -> 2245.057
B38: 수평연결재 | D38: ㎡ | G38: =SUM(E38:F38) -> 0
A39: 비계 | B39: 시스템비계 | C39: H=0~10M | D39: ㎡ | E39: ='[131]갈전7교 교량 일반수량 집계표'!$H$17 -> 739.883 | G39: =SUM(E39:F39) -> 739.883
B40: 비계다리 | D40: m | G40: =SUM(E40:F40) -> 0
...

Sheet 철근총괄
A2: =" < "&간지!$Z$3&" > ( SD400 ) " -> < 갈전7교 > ( SD400 )
A3: 공 종 | B3: 구분 | C3: 단위 | D3: H 32 | E3: H 29 | F3: H 25 | G3: H 22 | H3: H 19 | I3: H 16 | J3: H 13 | K3: H 10 | L3: 계 | O3: 도면에서 확인 후 입력
A4: 갈전7교 | B4: NET | C4: Ton | F4: ='[131]갈전7교 교량 철근수량 집계표'!$M$17 -> 60.944 | G4: ='[131]갈전7교 교량 철근수량 집계표'!$M$19 -> 51.284 | H4: ='[131]갈전7교 교량 철근수량 집계표'!$M$21 -> 20.418 | I4: ='[131]갈전7교 교량 철근수량 집계표'!$M$23 -> 30.885 | J4: ='[131]갈전7교 교량 철근수량 집계표'!$M$25 -> 5.676 | L4: =IF(SUM(D4:K4)>0,SUM(D4:K4),"") -> 169.207 | P4: A1 | Q4: A2 | R4: 합 계
B5: ADD | E5: =ROUND(E4*1.06,3) -> 0 | F5: =ROUND(F4*1.06,3) -> 64.601 | G5: =ROUND(G4*1.06,3) -> 54.361 | H5: =ROUND(H4*1.03,3) -> 21.031 | I5: =ROUND(I4*1.03,3) -> 31.812 | J5: =ROUND(J4*1.03,3) -> 5.846 | L5: =IF(SUM(D5:K5)>0,SUM(D5:K5),"") -> 177.651
A6: PSC E-BEAM | B6: NET | C6: Ton | L6: =IF(SUM(D6:K6)>0,SUM(D6:K6),"")
B7: ADD | D7: =ROUND(D6*1.06,3) -> 0 | E7: =ROUND(E6*1.06,3) -> 0 | L7: =IF(SUM(D7:K7)>0,SUM(D7:K7),"")
B8: NET | C8: Ton
B9: ADD | F9: =ROUND(F8*1.06,3) -> 0 | G9: =ROUND(G8*1.06,3) -> 0 | H9: =ROUND(H8*1.03,3) -> 0 | I9: =ROUND(I8*1.03,3) -> 0 | J9: =ROUND(J8*1.03,3) -> 0
B10: NET | C10: Ton | L10: =IF(SUM(D10:K10)>0,SUM(D10:K10),"")
B11: ADD | F11: =ROUND(F10*1.06,3) -> 0 | G11: =ROUND(G10*1.06,3) -> 0 | H11: =ROUND(H10*1.03,3) -> 0 | I11: =ROUND(I10*1.03,3) -> 0 | J11: =ROUND(J10*1.03,3) -> 0 | L11: =IF(SUM(D11:K11)>0,SUM(D11:K11),"")
B12: NET | C12: Ton | L12: =IF(SUM(D12:K12)>0,SUM(D12:K12),"")
B13: ADD | D13: =ROUND(D12*1.06,3) -> 0 | E13: =ROUND(E12*1.06,3) -> 0 | L13: =IF(SUM(D13:K13)>0,SUM(D13:K13),"")
A14: 가로등 기초 | B14: NET | C14: Ton | L14: =IF(SUM(D14:K14)>0,SUM(D14:K14),"") | O14: H25 | R14: =SUM(P14:Q14) -> 0
B15: ADD | D15: =ROUND(D14*1.06,3) -> 0 | E15: =ROUND(E14*1.06,3) -> 0 | F15: =ROUND(F14*1.06,3) -> 0 | G15: =ROUND(G14*1.06,3) -> 0 | H15: =ROUND(H14*1.03,3) -> 0 | I15: =ROUND(I14*1.03,3) -> 0 | J15: =ROUND(J14*1.03,3) -> 0 | K15: =ROUND(K14*1.03,3) -> 0 | L15: =IF(SUM(D15:K15)>0,SUM(D15:K15),"") | O15: H22 | R15: =SUM(P15:Q15) -> 0
A16: 옹벽공 | B16: NET | C16: Ton | L16: =IF(SUM(D16:K16)>0,SUM(D16:K16),"") | O16: H19 | R16: =SUM(P16:Q16) -> 0
B17: ADD | D17: =ROUND(D16*1.06,3) -> 0 | E17: =ROUND(E16*1.06,3) -> 0 | F17: =ROUND(F16*1.06,3) -> 0 | G17: =ROUND(G16*1.06,3) -> 0 | H17: =ROUND(H16*1.03,3) -> 0 | I17: =ROUND(I16*1.03,3) -> 0 | J17: =ROUND(J16*1.03,3) -> 0 | K17: =ROUND(K16*1.03,3) -> 0 | L17: =IF(SUM(D17:K17)>0,SUM(D17:K17),"") | O17: H16 | R17: =SUM(P17:Q17) -> 0
B18: NET | C18: Ton | L18: =IF(SUM(D18:K18)>0,SUM(D18:K18),"")
B19: ADD | D19: =ROUND(D18*1.06,3) -> 0 | E19: =ROUND(E18*1.06,3) -> 0 | F19: =ROUND(F18*1.06,3) -> 0 | G19: =ROUND(G18*1.06,3) -> 0 | H19: =ROUND(H18*1.03,3) -> 0 | I19: =ROUND(I18*1.03,3) -> 0 | J19: =ROUND(J18*1.03,3) -> 0 | K19: =ROUND(K18*1.03,3) -> 0 | L19: =IF(SUM(D19:K19)>0,SUM(D19:K19),"")
B20: NET | C20: Ton | L20: =IF(SUM(D20:K20)>0,SUM(D20:K20),"")
B21: ADD | L21: =IF(SUM(D21:K21)>0,SUM(D21:K21),"")
B22: NET | C22: Ton | L22: =IF(SUM(D22:K22)>0,SUM(D22:K22),"")
B23: ADD | L23: =IF(SUM(D23:K23)>0,SUM(D23:K23),"")
B24: NET | C24: Ton | L24: =IF(SUM(D24:K24)>0,SUM(D24:K24),"")
B25: ADD | L25: =IF(SUM(D25:K25)>0,SUM(D25:K25),"")
B26: NET | C26: Ton
B27: ADD | D27: =ROUND(D26*1.06,3) -> 0 | E27: =ROUND(E26*1.06,3) -> 0 | F27: =ROUND(F26*1.06,3) -> 0 | G27: =ROUND(G26*1.06,3) -> 0
B28: NET | C28: Ton
B29: ADD | F29: =ROUND(F28*1.06,3) -> 0 | H29: =ROUND(H28*1.03,3) -> 0 | I29: =ROUND(I28*1.03,3) -> 0 | J29: =ROUND(J28*1.03,3) -> 0 | K29: =ROUND(K28*1.03,3) -> 0 | L29: =IF(SUM(D29:K29)>0,SUM(D29:K29),"")
B30: NET | C30: Ton | L30: =IF(SUM(D30:K30)>0,SUM(D30:K30),"")
B31: ADD | L31: =IF(SUM(D31:K31)>0,SUM(D31:K31),"")
A32: 합 계 | B32: NET | C32: Ton | D32: =(D10+D12+D4+D6+D8+D14+D16+D18+D20+D22+D24+D26+D28) -> 0 | E32: =(E10+E12+E4+E6+E8+E14+E16+E18+E20+E22+E24+E26+E28) -> 0 | F32: =(F10+F12+F4+F6+F8+F14+F16+F18+F20+F22+F24+F26+F28) -> 60.944 | G32: =(G10+G12+G4+G6+G8+G14+G16+G18+G20+G22+G24+G26+G28) -> 51.284 | H32: =(H10+H12+H4+H6+H8+H14+H16+H18+H20+H22+H24+H26+H28) -> 20.418 | I32: =(I10+I12+I4+I6+I8+I14+I16+I18+I20+I22+I24+I26+I28) -> 30.885 | J32: =(J10+J12+J4+J6+J8+J14+J16+J18+J20+J22+J24+J26+J28) -> 5.676 | L32: =SUM(D32:K32) -> 169.207
B33: ADD | D33: =(D11+D13+D5+D7+D9+D15+D17+D19+D21+D23+D25+D27+D29) -> 0 | E33: =(E11+E13+E5+E7+E9+E15+E17+E19+E21+E23+E25+E27+E29) -> 0 | F33: =(F11+F13+F5+F7+F9+F15+F17+F19+F21+F23+F25+F27+F29) -> 64.601 | G33: =(G11+G13+G5+G7+G9+G15+G17+G19+G21+G23+G25+G27+G29) -> 54.361 | H33: =(H11+H13+H5+H7+H9+H15+H17+H19+H21+H23+H25+H27+H29) -> 21.031 | I33: =(I11+I13+I5+I7+I9+I15+I17+I19+I21+I23+I25+I27+I29) -> 31.812 | J33: =(J11+J13+J5+J7+J9+J15+J17+J19+J21+J23+J25+J27+J29) -> 5.846 | L33: =SUM(D33:K33) -> 177.651 | M33: =L33-L32 -> 8.444
A35: =" < "&간지!$Z$3&" > ( SD300 ) " -> < 갈전7교 > ( SD300 )
A36: 공 종 | B36: 구분 | C36: 단위 | D36: D 32 | E36: D 29 | F36: D 25 | G36: D 22 | H36: D 19 | I36: D 16 | J36: D 13 | K36: D 10 | L36: 계
B37: NET | C37: Ton | L37: =IF(SUM(D37:K37)>0,SUM(D37:K37),"")
B38: ADD | L38: =IF(SUM(D38:K38)>0,SUM(D38:K38),"")
B39: NET | C39: Ton | L39: =IF(SUM(D39:K39)>0,SUM(D39:K39),"")
B40: ADD | L40: =IF(SUM(D40:K40)>0,SUM(D40:K40),"")
B41: NET | C41: Ton | L41: =IF(SUM(D41:K41)>0,SUM(D41:K41),"")
B42: ADD | L42: =IF(SUM(D42:K42)>0,SUM(D42:K42),"")
...
