Workbook

Sheet 토공수량 토공 집계표
A1: 토공수량 토공 집계표
A2: 공종 | D2: 단위 | E2: 시점측 | F2: 종점측 | G2: 계 | H2: 비고
A3: 터파기 | B3: 토사 | C3: (0~4m) | D3: ㎥ | E3: ='시점측 토공 산출근거'!Z49 -> 1605.406 | F3: ='종점측 토공 산출근거'!Z49 -> 142.725 | G3: =SUM(E3:F3) -> 1748.131
A4: 수중터파기 | B4: 토사 | D4: ㎥ | E4: ='시점측 토공 산출근거'!Z56 -> 908.309 | F4: ='종점측 토공 산출근거'!Z56 -> 2202.751 | G4: =SUM(E4:F4) -> 3111.06
C5: (4~6m) | D5: ㎥ | E5: ='시점측 토공 산출근거'!Z60 -> 180.29 | F5: ='종점측 토공 산출근거'!Z60 -> 154.249 | G5: =SUM(E5:F5) -> 334.539
A6: 물푸기 | D6: hr | E6: ='시점측 토공 산출근거'!Z76 -> 199.026 | F6: ='종점측 토공 산출근거'!Z76 -> 234.546 | G6: =SUM(E6:F6) -> 433.572
A7: 뒷채움 | D7: ㎥ | E7: ='시점측 토공 산출근거'!Z86 -> 621.918 | F7: ='종점측 토공 산출근거'!Z86 -> 577.987 | G7: =SUM(E7:F7) -> 1199.905
A8: 되메우기 | D8: ㎥ | E8: ='시점측 토공 산출근거'!Z99 -> 1976.894 | F8: ='종점측 토공 산출근거'!Z99 -> 1841.291 | G8: =SUM(E8:F8) -> 3818.185
A9: 유용토 | D9: ㎥ | E9: ='시점측 토공 산출근거'!Z103 -> 717.111 | F9: ='종점측 토공 산출근거'!Z103 -> 658.434 | G9: =SUM(E9:F9) -> 1375.545
A10: 공제토 | C10: 노상 | D10: ㎥ | E10: ='시점측 토공 산출근거'!Z108 -> 252.36 | F10: ='종점측 토공 산출근거'!Z108 -> 234.223 | G10: =SUM(E10:F10) -> 486.583
C11: 노체 | D11: ㎥ | E11: ='시점측 토공 산출근거'!Z112 -> 147.247 | F11: ='종점측 토공 산출근거'!Z112 -> 143.811 | G11: =SUM(E11:F11) -> 291.058

Sheet 시점측 토공 산출근거
A1: 갈전7교
A2: 공 종 | E2: 산 출 근 거 | Z2: 수 량
A47: 1. 터파기 | F47: [(0~4m)]
A48: (토사) | G48: ((( | H48: 16.786 | J48: x | K48: 52.561 | M48: ) | N48: + | O48: ( | P48: 12.456 | R48: x | S48: 48.231 | U48: )) | AB48: ㎥
G49: / | H49: 2 | I49: ) | J49: x | K49: 2.165 | V49: = | W49: =ROUND((((H48*K48)+(P48*S48))/H49)*K49, 3) -> 1605.406 | Z49: =ROUND(SUM(W49:X49), 3) -> 1605.406
A52: 2. 수중터파기 | F52: [(0~4m)]
A53: ( 토사 ) | G53: ((( | H53: 12.456 | J53: x | K53: 48.231 | M53: ) | N53: + | O53: ( | P53: 11.656 | R53: x | S53: 47.431 | U53: ))
G54: / | H54: 2 | I54: ) | J54: x | K54: 0.4 | V54: = | W54: =ROUND((((H53*K53)+(P53*S53))/H54)*K54, 3) -> 230.724
G55: ((( | H55: 11.656 | J55: x | K55: 47.431 | M55: ) | N55: + | O55: ( | P55: 8.786 | R55: x | S55: 44.561 | U55: )) | AB55: ㎥
G56: / | H56: 2 | I56: ) | J56: x | K56: 1.435 | V56: = | W56: =ROUND((((H55*K55)+(P55*S55))/H56)*K56, 3) -> 677.585 | Z56: =ROUND(SUM(W54:Y56), 3) -> 908.309
F58: [(4~6m)]
G59: ((( | H59: 8.786 | J59: x | K59: 44.561 | M59: ) | N59: + | O59: ( | P59: 7.8 | R59: x | S59: 43.575 | U59: )) | AB59: ㎥
G60: / | H60: 2 | I60: ) | J60: x | K60: 0.493 | V60: = | W60: =ROUND((((H59*K59)+(P59*S59))/H60)*K60, 3) -> 180.29 | Z60: =ROUND(SUM(W60:X60), 3) -> 180.29
A63: 3. 물푸기 | G63: ① 토사
G64: - 터파기(4m 미만)
G65: - 터파기(백호우 1.0㎥) : θ = 53.46㎥/hr ÷ 1.5 = 35.64㎥/hr
G66: - 토사 물푸기 시간 :
G67: 토사 수중, 터파기량(908.309㎥) ÷ 35.64㎥/hr = 25.486hr
G68: - 터파기(4m 이상)
G69: - 터파기(백호우 1.0㎥) : θ = 48.81㎥/hr ÷ 1.5 = 32.54㎥/hr
G70: - 토사 물푸기 시간 :
G71: 토사 수중, 터파기량(180.290㎥) ÷ 32.54㎥/hr = 5.541hr
G73: A. 터파기 물푸기 시간 : ① = 31.026hr
G74: B. 거푸집 조립, 철근 조립 및 콘크리트 타설 = 48hr
G75: C. 콘크리트 양생, 거푸집 해체 = 120hr | AB75: hr
F76: ∴ 총 물푸기 시간 : A + B + C= 31.026 + 48.000 + 120.000 = 199.026hr | Z76: 199.026
A79: 4. 뒷채움 | F79: (뒷채움)
G80: ((( | H80: 0.5 | J80: + | K80: 5.57 | M80: ) | N80: / | O80: 2 | P80: x | Q80: 5.07 | S80: ) | T80: x
G81: 41.575 | I81: ) | V81: = | W81: =ROUND((((H80+K80)/O80*Q80)*G81), 3) -> 639.733
F82: (접속슬래브 공제)
G83: (4.100 x 41.775 x 0.100) x 73.206% | V83: = | W83: -12.539
F84: (브라켓 공제)
G85: ((( | H85: 0.273 | J85: + | K85: 0.573 | M85: ) | N85: / | O85: 2 | P85: x | Q85: 0.3 | S85: ) | T85: x | AB85: ㎥
G86: 41.575 | I86: ) | V86: = | W86: =-ROUND((((H85+K85)/O85*Q85)*G86), 3) -> -5.276 | Z86: =ROUND(SUM(W81:Y86), 3) -> 621.918
A90: 5. 되메우기 | F90: * 되메우기 = 터파기 - (지반선 이하의 구체 및 뒷채움)
F91: (터파기)
G92: =ROUND(W49+W54+W56+W60, 3) -> 2694.005 | V92: = | W92: =ROUND(G92, 3) -> 2694.005
F93: (구체공제)
F94: ① | G94: 41.575 | I94: x | J94: 5.8 | L94: x | M94: 1 | V94: = | W94: =-ROUND(G94*J94*M94, 3) -> -241.135
F95: ③ | G95: 1 | I95: x | J95: 3.393 | L95: x | M95: 41.575 | V95: = | W95: =-ROUND(G95*J95*M95, 3) -> -141.064
...

Sheet 종점측 토공 산출근거
A1: 갈전7교
A2: 공 종 | E2: 산 출 근 거 | Z2: 수 량
A47: 1. 터파기 | F47: [(0~4m)]
A48: (토사) | G48: ((( | H48: 16.71 | J48: x | K48: 49.497 | M48: ) | N48: + | O48: ( | P48: 16.36 | R48: x | S48: 49.147 | U48: )) | AB48: ㎥
G49: / | H49: 2 | I49: ) | J49: x | K49: 0.175 | V49: = | W49: =ROUND((((H48*K48)+(P48*S48))/H49)*K49, 3) -> 142.725 | Z49: =ROUND(SUM(W49:X49), 3) -> 142.725
A52: 2. 수중터파기 | F52: [(0~4m)]
A53: ( 토사 ) | G53: ((( | H53: 16.36 | J53: x | K53: 49.147 | M53: ) | N53: + | O53: ( | P53: 11.58 | R53: x | S53: 44.367 | U53: ))
G54: / | H54: 2 | I54: ) | J54: x | K54: 2.39 | V54: = | W54: =ROUND((((H53*K53)+(P53*S53))/H54)*K54, 3) -> 1574.789
G55: ((( | H55: 11.58 | J55: x | K55: 44.367 | M55: ) | N55: + | O55: ( | P55: 8.71 | R55: x | S55: 41.497 | U55: )) | AB55: ㎥
G56: / | H56: 2 | I56: ) | J56: x | K56: 1.435 | V56: = | W56: =ROUND((((H55*K55)+(P55*S55))/H56)*K56, 3) -> 627.962 | Z56: =ROUND(SUM(W54:Y56), 3) -> 2202.751
F58: [(4~6m)]
G59: ((( | H59: 8.71 | J59: x | K59: 41.497 | M59: ) | N59: + | O59: ( | P59: 7.8 | R59: x | S59: 40.587 | U59: )) | AB59: ㎥
G60: / | H60: 2 | I60: ) | J60: x | K60: 0.455 | V60: = | W60: =ROUND((((H59*K59)+(P59*S59))/H60)*K60, 3) -> 154.249 | Z60: =ROUND(SUM(W60:X60), 3) -> 154.249
A63: 3. 물푸기 | G63: ① 토사
G64: - 터파기(4m 미만)
G65: - 터파기(백호우 1.0㎥) : θ = 53.46㎥/hr ÷ 1.5 = 35.64㎥/hr
G66: - 토사 물푸기 시간 :
G67: 토사 수중, 터파기량(2202.751㎥) ÷ 35.64㎥/hr = 61.806hr
G68: - 터파기(4m 이상)
G69: - 터파기(백호우 1.0㎥) : θ = 48.81㎥/hr ÷ 1.5 = 32.54㎥/hr
G70: - 토사 물푸기 시간 :
G71: 토사 수중, 터파기량(154.249㎥) ÷ 32.54㎥/hr = 4.740hr
G73: A. 터파기 물푸기 시간 : ① = 66.546hr
G74: B. 거푸집 조립, 철근 조립 및 콘크리트 타설 = 48hr
G75: C. 콘크리트 양생, 거푸집 해체 = 120hr | AB75: hr
F76: ∴ 총 물푸기 시간 : A + B + C= 66.546 + 48.000 + 120.000 = 234.546hr | Z76: 234.546
A79: 4. 뒷채움 | F79: (뒷채움)
G80: ((( | H80: 0.5 | J80: + | K80: 5.57 | M80: ) | N80: / | O80: 2 | P80: x | Q80: 5.07 | S80: ) | T80: x
G81: 38.587 | I81: ) | V81: = | W81: =ROUND((((H80+K80)/O80*Q80)*G81), 3) -> 593.756
F82: (접속슬래브 공제)
G83: (4.100 x 38.787 x 0.100) x 68.663% | V83: = | W83: -10.919
F84: (브라켓 공제)
G85: ((( | H85: 0.569 | J85: + | K85: 0.269 | M85: ) | N85: / | O85: 2 | P85: x | Q85: 0.3 | S85: ) | T85: x | AB85: ㎥
G86: 38.587 | I86: ) | V86: = | W86: =-ROUND((((H85+K85)/O85*Q85)*G86), 3) -> -4.85 | Z86: =ROUND(SUM(W81:Y86), 3) -> 577.987
A90: 5. 되메우기 | F90: * 되메우기 = 터파기 - (지반선 이하의 구체 및 뒷채움)
F91: (터파기)
G92: =ROUND(W49+W54+W56+W60, 3) -> 2499.725 | V92: = | W92: =ROUND(G92, 3) -> 2499.725
F93: (구체공제)
F94: ② | G94: 38.587 | I94: x | J94: 5.8 | L94: x | M94: 1 | V94: = | W94: =-ROUND(G94*J94*M94, 3) -> -223.805
F95: ④ | G95: 1 | I95: x | J95: 3.355 | L95: x | M95: 38.587 | V95: = | W95: =-ROUND(G95*J95*M95, 3) -> -129.459
...

Sheet Sheet1
