Workbook
Name HMAX: #N/A
Name LLFE: #N/A
Name VMAX: #N/A
Name ㅍ49: #REF!
Name ㅍ49: #REF!

Sheet 간지
A1: 1) 가 시 설 공

Sheet 0-1)가시설 수량 집계표
A1: 가시설 수량 집계표
A2: 공 종 | B2: 규 격 | D2: 시점 | E2: 종점 | H2: 계 | I2: 비 고
A3: H-PILE 천공 | B3: 토사 | C3: M | H3: =SUM(D3:G3) -> 0
B4: 연암 | C4: M | H4: =SUM(D4:G4) -> 0
A5: H-PILE 항타 | B5: 슬라임부 | C5: 본
A6: 케이싱 튜브 설치 철거 | C6: M | H6: =SUM(D6:G6) -> 0
A7: H-PILE 두부정리 | C7: 개소
A8: H-PILE 연결 및 해체 | C8: 본
A9: 모래 채움 | C9: M3
A10: H-PILE 인발 | C10: M | H10: =SUM(D10:G10) -> 0
A11: 토류판 설치 및 철거 | B11: 200x100x50x1.0t | C11: M2 | H11: =SUM(D11:G11) -> 0
A12: 어스앵커 천공 | B12: 토사 | C12: M | H12: =SUM(D12:G12) -> 0
B13: 연암 | C13: M | H13: =SUM(D13:G13) -> 0
A14: P.C 강선 조립 및 삽입 | C14: 공 | H14: =SUM(D14:G14) -> 0
A15: 그라우팅 | B15: EARTH ANCHOR용 | C15: M3 | H15: =SUM(D15:G15) -> 0
A16: P.C 콘 조립 및 인장 | C16: 공 | H16: =SUM(D16:G16) -> 0
A17: 지압판 제작 및 설치 | C17: 공 | H17: =SUM(D17:G17) -> 0
A18: 지압판 철거 | C18: 공 | H18: =SUM(D18:G18) -> 0
A19: SHEET PILE 항타 | B19: 토사 | C19: M | D19: =시점!AA48 -> 3814.44 | E19: =종점!AA48 -> 3074.4 | H19: =SUM(D19:G19) -> 6888.84
B20: 연암 | C20: M | D20: =시점!AA51 -> 0 | E20: =종점!AA54 -> 0 | H20: =SUM(D20:G20) -> 0
A21: SHEET PILE 인발 | C21: M | D21: =시점!AA65 -> 3814.44 | E21: =종점!AA65 -> 3074.4 | H21: =SUM(D21:G21) -> 6888.84
A22: 장비조립 및 해체 | C22: 개소 | D22: 1 | E22: 1 | H22: =SUM(D22:G22) -> 2
A23: 가이드 빔 기준틀 제작 | B23: 직선형 기준틀 | C23: 본 | D23: =시점!AA20 -> 1 | E23: =종점!AA20 -> 1 | H23: =SUM(D23:G23) -> 2
A24: 가이드빔 기준틀 이동 및 설치 | B24: H-250x250x9x14 | C24: 회 | D24: =시점!AB32 -> 11 | E24: =종점!AB32 -> 11 | H24: =SUM(D24:G24) -> 22
A25: 지수제 도포 | C25: M | D25: =시점!AA58 -> 3814.44 | E25: =종점!AA58 -> 3074.4 | H25: =SUM(D25:G25) -> 6888.84
A26: SHEET PILE 코너 파일 제작 | C26: 개소 | D26: =시점!AA38 -> 4 | E26: =종점!AA38 -> 4 | H26: =SUM(D26:G26) -> 8
A27: 띠장 설치 및 철거 | B27: 9-11m, H=0~250 | C27: 본 | H27: =SUM(D27:G27) -> 0
B28: 12-14m, H=0~250 | C28: 본 | H28: =SUM(D28:G28) -> 0
B29: 15-18m, H=0~250 | C29: 본 | H29: =SUM(D29:G29) -> 0
A30: 띠장 설치 및 철거 | B30: 6-8m, H=300~500 | C30: 본 | D30: =시점!AA74 -> 4 | E30: =종점!AA74 -> 4 | H30: =SUM(D30:G30) -> 8
B31: 9-11m, H=300~500 | C31: 본 | D31: =시점!AA76 -> 16 | E31: =종점!AA76 -> 16 | H31: =SUM(D31:G31) -> 32
B32: 15-18m, H=300~500 | C32: 본
A33: 띠장 이음 및 해체 | B33: H-300x300x10x15 | C33: 개소 | D33: =시점!AA103 -> 12 | E33: =종점!AA103 -> 12 | H33: =SUM(D33:G33) -> 24
A34: 띠장 우각부 연결 및 해체 | B34: H-300x300x10x15 | C34: 개소 | D34: =시점!AA91 -> 8 | E34: =종점!AA91 -> 8 | H34: =SUM(D34:G34) -> 16
A35: 보걸이 설치 및 철거 | B35: φ22 | C35: 개소
B36: L-90x90x10 | C36: 개소 | D36: =시점!AA117 -> 76 | E36: =종점!AA117 -> 68 | H36: =SUM(D36:G36) -> 144
A37: 버팀보 제작 | B37: H-300x300x10x15 | C37: 개소 | D37: =시점!AA85 -> 38 | E37: =종점!AA85 -> 34 | H37: =SUM(D37:G37) -> 72
A38: 버팀보 설치 및 철거 | B38: 7-9m, H=300~500 | C38: 본 | D38: =시점!AA85 -> 38 | E38: =종점!AA85 -> 34 | H38: =SUM(D38:G38) -> 72
A39: 경사 버팀보 제작 | B39: H-300x300x10x15 | C39: 개소 | D39: =시점!AA131 -> 8 | E39: =종점!AA131 -> 8 | H39: =SUM(D39:G39) -> 16
A40: 경사 버팀보 설치 및 철거 | B40: 4-6m, H=300~500 | C40: 본 | D40: =시점!AA131 -> 8 | E40: =종점!AA131 -> 8 | H40: =SUM(D40:G40) -> 16
...

Sheet 0-2) 가시설 자재 집계표
A1: 가시설 자재 집계표
A2: 공 종 | C2: 규 격 | H2: 단위 | I2: 시점 | J2: 종점 | P2: 계 | Q2: 비 고
A3: Sheet-Pile | C3: 400x125x13 | H3: tonf | I3: =시점!AA16 -> 236.846 | J3: =종점!AA16 -> 192.024 | P3: =SUM(I3:O3) -> 428.87 | Q3: NET
A4: 할증 계 | H4: tonf | I4: =ROUND(I3*1.07,3) -> 253.425 | J4: =ROUND(J3*1.07,3) -> 205.466 | P4: =SUM(I4:O4) -> 458.891 | Q4: ADD 7%
A5: 띠장 | C5: H-300x300x10x15 | H5: tonf | I5: =시점!AA78 -> 19.552 | J5: =종점!AA78 -> 18.443
A6: 경사 버팀보(L=4.400m) | H6: tonf | I6: =ROUND(시점!X133*시점!AA131,3) -> 3.309 | J6: =ROUND(종점!X133*종점!AA131,3) -> 3.309 | P6: =SUM(I6:O6) -> 6.618
A7: 사보강재(L=1.800m) | H7: tonf | I7: =ROUND(시점!X168*시점!AA167,3) -> 1.354 | J7: =ROUND(종점!X168*종점!AA167,3) -> 1.354 | P7: =SUM(I7:O7) -> 2.708
A8: 계 | H8: tonf | I8: =SUM(I5:I7) -> 24.215 | J8: =SUM(J5:J7) -> 23.106 | P8: =SUM(I8:O8) -> 47.321 | Q8: NET
A9: 할증 계 | H9: tonf | I9: =ROUND(I8*1.07,3) -> 25.91 | J9: =ROUND(J8*1.07,3) -> 24.723 | P9: =SUM(I9:O9) -> 50.633 | Q9: ADD 7%
A10: H-PILE | C10: H-300x300x10x15 | H10: tonf | P10: =SUM(I10:O10) -> 0 | Q10: NET
A11: 할증 계 | H11: tonf | P11: =SUM(I11:O11) -> 0 | Q11: ADD 7%
A12: 어스앵카용 띠장 | C12: H-250x250x9x14 | H12: tonf | P12: =SUM(I12:O12) -> 0 | Q12: NET
A13: 할증 계 | H13: tonf | P13: =SUM(I13:O13) -> 0 | Q13: ADD 7%
A14: 버팀보용 띠장 | C14: H-300x300x10x15 | H14: tonf | I14: =시점!AA87 -> 26.433 | J14: =종점!AA87 -> 23.65 | P14: =SUM(I14:O14) -> 50.083 | Q14: NET
A15: 할증 계 | H15: tonf | I15: =ROUND(I14*1.07,3) -> 28.283 | J15: =ROUND(J14*1.07,3) -> 25.306 | P15: =SUM(I15:O15) -> 53.589 | Q15: ADD 7%
A16: 가이드 빔 및 파일 | C16: H-250x250x9x14 | H16: tonf | I16: =시점!AA26 -> 2.896 | J16: =종점!AA26 -> 2.896 | P16: =SUM(I16:O16) -> 5.792 | Q16: NET
A17: 할증 계 | H17: tonf | I17: =ROUND(I16*1.07,3) -> 3.099 | J17: =ROUND(J16*1.07,3) -> 3.099 | P17: =SUM(I17:O17) -> 6.198 | Q17: ADD 7%
A18: ㄷ-형강 | C18: ㄷ-380x100x10.5x16 | H18: tonf | I18: =시점!AA204 -> 0.523 | J18: =종점!AA204 -> 0.523 | P18: =SUM(I18:O18) -> 1.046 | Q18: NET
A19: 할증 계 | H19: tonf | I19: =ROUND(I18*1.07,3) -> 0.56 | J19: =ROUND(J18*1.07,3) -> 0.56 | P19: =SUM(I19:O19) -> 1.12 | Q19: ADD 7%
A20: ㄷ-형강 | C20: ㄷ-150x75x6.5x10 | H20: tonf | I20: =시점!AA223 -> 7.172 | J20: =종점!AA223 -> 6.387 | P20: =SUM(I20:O20) -> 13.559 | Q20: NET
A21: 할증 계 | H21: tonf | I21: =ROUND(I20*1.07,3) -> 7.674 | J21: =ROUND(J20*1.07,3) -> 6.834 | P21: =SUM(I21:O21) -> 14.508 | Q21: ADD 7%
A22: L-형강 | C22: L-130x130x9 | H22: tonf | I22: =시점!AA217 -> 1.837 | J22: =종점!AA217 -> 1.643 | P22: =SUM(I22:O22) -> 3.48 | Q22: NET
A23: =A19 -> 할증 계 | H23: tonf | I23: =ROUND(I22*1.05,3) -> 1.929 | J23: =ROUND(J22*1.05,3) -> 1.725 | P23: =SUM(I23:O23) -> 3.654 | Q23: ADD 5%
A24: L-형강 | C24: L-90x90x10 | H24: tonf | I24: =시점!AA119 -> 1.553 | J24: =종점!AA119 -> 1.389 | P24: =SUM(I24:O24) -> 2.942 | Q24: NET
A25: =A23 -> 할증 계 | H25: tonf | I25: =ROUND(I24*1.05,3) -> 1.631 | J25: =ROUND(J24*1.05,3) -> 1.458 | P25: =SUM(I25:O25) -> 3.089 | Q25: ADD 5%
A26: 강 판 | C26: t=12mm | H26: tonf | P26: =SUM(I26:O26) -> 0 | Q26: NET
A27: =A23 -> 할증 계 | H27: tonf | P27: =SUM(I27:O27) -> 0 | Q27: ADD 10%
A28: 강 판 | C28: t=14 mm | H28: tonf | I28: =SUM(시점!AG94:AG197) -> 4.0720324 | J28: =SUM(종점!AG94:AG197) -> 3.7278256 | P28: =SUM(I28:O28) -> 7.799858 | Q28: NET
A29: =A27 -> 할증 계 | H29: tonf | I29: =ROUND(I28*1.1,3) -> 4.479 | J29: =ROUND(J28*1.1,3) -> 4.101 | P29: =SUM(I29:O29) -> 8.58 | Q29: ADD 10%
A30: 강 판 | C30: t=25 mm | H30: tonf | P30: =SUM(I30:O30) -> 0 | Q30: NET
A31: =A29 -> 할증 계 | H31: tonf | P31: =SUM(I31:O31) -> 0 | Q31: ADD 10%
A32: JACK | C32: 100 tonf | H32: 개소 | I32: =시점!AB162 -> 46 | J32: =종점!AB162 -> 42 | P32: =SUM(I32:O32) -> 88
A33: PC 강연선 | C33: Ф12.7 - 5EA | H33: m | P33: =SUM(I33:O33) -> 0
A34: ROCK BOLT | C34: L=5.0m | H34: 개소 | P34: =SUM(I34:O34) -> 0
I35: 공 종 | J35: 규 격 | L35: NET 계 | M35: 할증 계
I36: H-BEAM | J36: H-250x250x9x14 | L36: =P12+P16 -> 5.792 | M36: =P13+P17 -> 6.198
J37: H-300x300x10x15 | L37: =P8+P10+P14 -> 97.404 | M37: =P9+P11+P15 -> 104.222
I38: 계 | L38: =L36+L37 -> 103.196 | M38: =M36+M37 -> 110.42
I39: Sheet-Pile | J39: 400x125x13 | L39: =P3 -> 428.87 | M39: =P4 -> 458.891

Sheet 시점
A1: 갈전7교 | AA1: P1(좌측)
A2: 공 종 | F2: 산 출 근 거
M3: 시점
A5: 1. SHEET-PILE 자재비
F6: 400x125x13 , H = | K6: 14.84 | N6: m
G8: SHEET-PILE 본수
H10: 8.65 | K10: ÷ | L10: 0.4 | N10: = | O10: =FIXED(H10/L10,0) -> 22 | Q10: 본
H11: 44.45 | K11: ÷ | L11: 0.4 | N11: = | O11: =FIXED(H11/L11,0) -> 111 | Q11: 본
K12: =O10+O11 -> 133 | M12: 본 | N12: x | O12: 2 | P12: 면 | Q12: = | R12: =K12*O12 -> 266 | U12: 본 | W12: = | X12: =R12 -> 266 | Z12: 본 | AD12: 본
AA13: =X12 -> 266
G14: SHEET-PILE 자재비
Y15: tonf | AC15: tonf
H16: =K6 -> 14.84 | K16: x | L16: =AA13 -> 266 | N16: 본 | O16: x | P16: 0.06 | R16: tonf/m | W16: = | X16: =ROUND(H16*L16*P16,3) -> 236.846 | AA16: =X16 -> 236.846
A19: 2. 가이드 빔 | F19: ⓐ | G19: 가이드 빔 | J19: 4 | K19: 회 운용 | AC19: 개소
A20: 기준틀 제작 | G20: H-250×250×9×14 | M20: : | N20: 2 | O20: 본 | P20: 1조 | AA20: 1
G21: 가이드 빔 길이 : | M21: 10 | P21: m
F22: ⓑ | G22: 가이드 파일
G23: H-250×250×9×14 | M23: - | N23: 4 | O23: 본 | P23: 1조
G24: 가이드 파일 길이 : | M24: 5 | P24: m
Q25: tonf/m | AC25: tonf
F26: ⓒ | G26: 자재비 | I26: : | J26: =M21*N20+M24*N23 -> 40 | M26: x | N26: =AA20 -> 1 | O26: 본 | P26: x | Q26: 0.0724 | W26: = | X26: =ROUND(J26*N26*Q26,3) -> 2.896 | AA26: =X26 -> 2.896
A30: 3. 가이드 빔 기준틀 | H30: =(H10+H11)*2 -> 106.2 | K30: / | L30: 10 | N30: M당 1회
A31: 이동 및 설치
AB32: =ROUNDUP(H30/L30,0) -> 11 | AD32: 회
A35: 4. Corner Sheet-Pile 제작 | G35: H = | H35: =K6 -> 14.84 | K35: m
H37: - 전체 설치 개소 | M37: : | N37: 4 | O37: 개소 | AC37: 개소
H38: 단위 수량표(개소당) | AA38: =N37 -> 4
H39: 구 분 | M39: 치 수 | P39: 수 량 | U39: 비 고
H40: Sheet Pile 절단 | M40: 13 mm | P40: =H35 -> 14.84 | T40: m
H41: 형강 L-90x90x10 | M41: L =0.150m | P41: =FIXED(H35/1,0) -> 15 | T41: EA
H42: 필렛용접 | M42: 6mm | P42: =P40+(0.15*2+0.09*2)*P41 -> 22.04 | T42: m
A45: 5. Sheet Pile 항타 | G45: 400x125x13
G47: ⓐ | H47: 토사 | AD47: m
H48: 14.34 | K48: x | L48: =AA13 -> 266 | N48: EA | W48: ＝ | X48: =ROUND(H48*L48,3) -> 3814.44 | AA48: =+X48 -> 3814.44
G50: ⓑ | H50: 풍화암 | AD50: m
H51: 0 | K51: x | L51: =L48 -> 266 | N51: EA | W51: ＝ | X51: =ROUND(H51*L51,3) -> 0 | AA51: =+X51 -> 0
G53: ⓒ | H53: 연암 | AD53: m
H54: 0 | K54: x | L54: =L51 -> 266 | N54: EA | W54: ＝ | X54: =ROUND(H54*L54,3) -> 0 | AA54: =+X54 -> 0
A57: 6. Sheet Pile | G57: =K6-0.5 -> 14.34 | J57: x | K57: =AA13 -> 266 | M57: 본 | W57: = | X57: =G57*K57 -> 3814.44 | AD57: m
A58: 지수재 도포 | AA58: =X57 -> 3814.44
...

Sheet 종점
A1: 갈전7교 | AA1: P1(좌측)
A2: 공 종 | F2: 산 출 근 거
M3: 시점
A5: 1. SHEET-PILE 자재비
F6: 400x125x13 , H = | K6: 12.7 | N6: m
G8: SHEET-PILE 본수
H10: 8.65 | K10: ÷ | L10: 0.4 | N10: = | O10: =FIXED(H10/L10,0) -> 22 | Q10: 본
H11: 41.5 | K11: ÷ | L11: 0.4 | N11: = | O11: =FIXED(H11/L11,0) -> 104 | Q11: 본
K12: =O10+O11 -> 126 | M12: 본 | N12: x | O12: 2 | P12: 면 | Q12: = | R12: =K12*O12 -> 252 | U12: 본 | W12: = | X12: =R12 -> 252 | Z12: 본 | AD12: 본
AA13: =X12 -> 252
G14: SHEET-PILE 자재비
Y15: tonf | AC15: tonf
H16: =K6 -> 12.7 | K16: x | L16: =AA13 -> 252 | N16: 본 | O16: x | P16: 0.06 | R16: tonf/m | W16: = | X16: =ROUND(H16*L16*P16,3) -> 192.024 | AA16: =X16 -> 192.024
A19: 2. 가이드 빔 | F19: ⓐ | G19: 가이드 빔 | J19: 4 | K19: 회 운용 | AC19: 개소
A20: 기준틀 제작 | G20: H-250×250×9×14 | M20: : | N20: 2 | O20: 본 | P20: 1조 | AA20: 1
G21: 가이드 빔 길이 : | M21: 10 | P21: m
F22: ⓑ | G22: 가이드 파일
G23: H-250×250×9×14 | M23: - | N23: 4 | O23: 본 | P23: 1조
G24: 가이드 파일 길이 : | M24: 5 | P24: m
Q25: tonf/m | AC25: tonf
F26: ⓒ | G26: 자재비 | I26: : | J26: =M21*N20+M24*N23 -> 40 | M26: x | N26: =AA20 -> 1 | O26: 본 | P26: x | Q26: 0.0724 | W26: = | X26: =ROUND(J26*N26*Q26,3) -> 2.896 | AA26: =X26 -> 2.896
A30: 3. 가이드 빔 기준틀 | H30: =(H10+H11)*2 -> 100.3 | K30: / | L30: 10 | N30: M당 1회
A31: 이동 및 설치
AB32: =ROUNDUP(H30/L30,0) -> 11 | AD32: 회
A35: 4. Corner Sheet-Pile 제작 | G35: H = | H35: =K6 -> 12.7 | K35: m
H37: - 전체 설치 개소 | M37: : | N37: 4 | O37: 개소 | AC37: 개소
H38: 단위 수량표(개소당) | AA38: =N37 -> 4
H39: 구 분 | M39: 치 수 | P39: 수 량 | U39: 비 고
H40: Sheet Pile 절단 | M40: 13 mm | P40: =H35 -> 12.7 | T40: m
H41: 형강 L-90x90x10 | M41: L =0.150m | P41: =FIXED(H35/1,0) -> 13 | T41: EA
H42: 필렛용접 | M42: 6mm | P42: =P40+(0.15*2+0.09*2)*P41 -> 18.94 | T42: m
A45: 5. Sheet Pile 천공 | G45: 400x125x13
A46: (Auger+T4)
G47: ⓐ | H47: 토사 천공 | AD47: m
H48: 12.2 | K48: x | L48: =AA13 -> 252 | N48: EA | O48: x | W48: ＝ | X48: =ROUND(H48*L48,3) -> 3074.4 | AA48: =+X48 -> 3074.4
G50: ⓑ | H50: 풍화암 천공 | AD50: m
H51: 0 | K51: x | L51: =L48 -> 252 | N51: EA | O51: x | W51: ＝ | X51: =ROUND(H51*L51,3) -> 0 | AA51: =+X51 -> 0
G53: ⓒ | H53: 연암 천공 | AD53: m
H54: 0 | K54: x | L54: =L51 -> 252 | N54: EA | O54: x | W54: ＝ | X54: =ROUND(H54*L54,3) -> 0 | AA54: =+X54 -> 0
A57: 6. Sheet Pile | G57: =K6-0.5 -> 12.2 | J57: x | K57: =AA13 -> 252 | M57: 본 | W57: = | X57: =G57*K57 -> 3074.4 | AD57: m
...
