Workbook
Name _E81161: [3]깨기!$E$51161
Name _H81192: [3]깨기!$H$51192
Name _H91164: [3]깨기!$H$11164
Name _hor1: [4]단면가정!$G$36
Name _IV65999: #REF!
Name _IV66000: #REF!
Name _IV69999: #REF!
Name _IV70000: #REF!
Name _IV99999: #REF!
Name _Q1: '[1]1. 설계조건 2.단면가정 3. 하중계산'!$I$89
Name _Q5: '[1]1. 설계조건 2.단면가정 3. 하중계산'!$I$97
Name _QL: '[1]1. 설계조건 2.단면가정 3. 하중계산'!$G$99
Name _SBB1: [2]Sheet1!$H$204
Name _SBB2: [2]Sheet1!$H$205
Name _SBB3: [2]Sheet1!$H$223
Name _SBB4: [2]Sheet1!$H$224
Name _SBB5: [2]Sheet1!$H$208
Name _SHH1: [2]Sheet1!$D$205
Name _SHH2: [2]Sheet1!$D$223
Name _SHH3: [2]Sheet1!$D$224
Name _SIN1: #REF!
Name _ver1: [4]단면가정!$C$16
Name _ver3: [4]단면가정!$C$30
Name _Zz10137: #REF!
Name \p: #REF!
Name A_1: #REF!
Name A1_E: #REF!
Name A1000000000000000: #REF!
Name AA: #REF!
Name aaa: #REF!
Name AAADFFFFFFFFFFFD: #REF!
Name abc: #REF!
Name abcdefg: #REF!
Name abcdefgh: #REF!
Name an1_ea: #REF!
Name an21_e: #REF!
Name an21_ea: #REF!
Name an22_ea: #REF!
Name ANGLE1: #REF!
Name ANGLE21: #REF!
Name ANGLE22: #REF!
Name asd: [2]Sheet1!#REF!
Name asd: [2]Sheet1!#REF!
Name asdf: #REF!
Name ASDFVBN: #REF!
Name AWDR: #REF!
Name AWSXC: #REF!
Name AXCV: #REF!
Name B: [2]Sheet1!$J$32
Name B1B: [2]Sheet1!$J$33
Name B2B: [2]Sheet1!$J$34
Name B3B: [2]Sheet1!$J$35
Name B4B: [2]Sheet1!$J$36
Name B5B: [2]Sheet1!#REF!
Name B5B: [2]Sheet1!#REF!
Name B6B: [2]Sheet1!#REF!
Name B6B: [2]Sheet1!#REF!
Name B7B: [2]Sheet1!#REF!
Name B7B: [2]Sheet1!#REF!
Name bbb: #REF!

Sheet D.C.M 수량집계표
A1: 번호 | B1: 공 종 | C1: 규 격 | D1: 단 위 | E1: 수 량 | F1: 비 고
A2: 1 | B2: 심층혼합처리(개량공) | C2: N≤5/점성토/L=10.0M, 56공 | D2: m | E2: ='D.C.M산출근거(본산)'!F36+'D.C.M산출근거(본산)'!E38 -> 560 | F2: ￠1,000×4rod, N<5
A3: 2 | B3: 심층혼합처리(공삭공) | C3: N≤5/점성토/L=10.0M, 56공 | D3: m | E3: ='D.C.M산출근거(본산)'!E40 -> 112 | F3: N<5
A4: 3 | B4: PILE DRIVER 및 PLANT 조립및해체 | C4: 외부반입/반출 | D4: 회 | E4: ='D.C.M산출근거(본산)'!D53 -> 28
A5: 4 | B5: PETMAT | C5: 2열, T=10tf/m | D5: m2 | E5: ='D.C.M산출근거(본산)'!F50 -> 0
A6: 5 | B6: 이토처리 | C6: B/H0.7㎥+D/T24ton | D6: m3 | E6: ='D.C.M산출근거(본산)'!I45 -> 344.27
A7: 6 | B7: 시 멘 트 | C7: Bulk | D7: TON | E7: ='D.C.M산출근거(본산)'!H42 -> 436.06 | F7: 할증율 3%포함

Sheet D.C.M산출근거(본산)
B1: 심 층 혼 합 공 법 수 량 산 출 근 거
B3: 9)본산 지반개량- 심층혼합공법 | G3: =D36 -> 10 | H3: -> A 구간
B4: (1)시공본수 - 심층혼합공법(￠1,000×4rod)
B5: 유등4교 A1 A= | C5: 250.65 | D5: =J5 -> 3.024 | E5: =C5/D5 -> 82.886905 | F5: =J6 -> 2.8 | I5: 1공당 면적 = | J5: 3.024
B6: 유등4교 A2 A= | C6: 250.65 | F6: =J6 -> 2.8 | I6: 1열 간격 = | J6: 2.8
B7: 우암교 A1 A= | C7: 250.65 | D7: =J7 -> 0 | E7: =C7/D7 -> #DIV/0! | F7: =J6 -> 2.8
B8: 우암교 A2 A= | C8: 250.65 | D8: =J8 -> 0 | E8: =C8/D8 -> #DIV/0! | F8: =J6 -> 2.8
B9: 모산1교 A1 A= | C9: 250.65 | F9: =J6 -> 2.8
B10: 모산1교 A2 A= | C10: 250.65 | F10: =J6 -> 2.8
B11: 모산2교 A1 A= | C11: 250.65 | F11: =J6 -> 2.8
B12: 모산2교 A2 A= | C12: 250.65 | F12: =J6 -> 2.8
B13: 모산4교 A1 A= | C13: 250.65 | F13: =J6 -> 2.8
B14: 모산4교 A2 A= | C14: 250.65 | F14: =J6 -> 2.8
B15: 갈전1교 A1 A= | C15: 250.65 | F15: =J6 -> 2.8
B16: 갈전1교 A2 A= | C16: 250.65 | F16: =J6 -> 2.8
B17: 갈전2교 A1 A= | C17: 250.65 | F17: =J6 -> 2.8
B18: 갈전2교 A2 A= | C18: 250.65 | F18: =J6 -> 2.8
B19: 갈전3교 A1 A= | C19: 250.65 | F19: =J6 -> 2.8
B20: 갈전3교 A2 A= | C20: 250.65 | F20: =J6 -> 2.8
B21: 갈전4교 A1 A= | C21: 250.65 | F21: =J6 -> 2.8
B22: 갈전4교 A2 A= | C22: 250.65 | F22: =J6 -> 2.8
B23: 갈전5교 A1 A= | C23: 250.65 | F23: =J6 -> 2.8
B24: 갈전5교 A2 A= | C24: 250.65 | F24: =J6 -> 2.8
B25: 송정교 A1 A= | C25: 250.65 | F25: =J6 -> 2.8
B26: 송정교 A2 A= | C26: 250.65 | F26: =J6 -> 2.8
B27: 갈전6교 A1 A= | C27: 250.65 | F27: =J6 -> 2.8
B28: 갈전6교 A2 A= | C28: 250.65 | F28: =J6 -> 2.8
B29: 갈전7교 A1 A= | C29: 250.65 | F29: =J6 -> 2.8 | G29: 28
B30: 갈전7교 A2 A= | C30: 250.65 | F30: =J6 -> 2.8 | G30: 28
B31: 갈전9교 A1 A= | C31: 250.65 | F31: =J6 -> 2.8
B32: 갈전9교 A2 A= | C32: 250.65 | F32: =J6 -> 2.8
C33: 계 | F33: = | G33: =SUM(G5:G32) -> 56
B35: (2)개량공 - 심층혼합공법(￠1,000×4rod,N≤5)
C36: =G33 -> 56 | D36: 10 | E36: = | F36: =C36*D36 -> 560
B37: (3)개량공 - 심층혼합공법(￠1,000×4rod,N≤5)
C38: 0 | D38: 0 | E38: =C38*D38 -> 0
B39: (4)공삭공 - 심층혼합공법(￠1,000×4rod) / 장비 주행성 확보 위한 복토 1.0m 포함
C40: =G33 -> 56 | D40: 2 | E40: =C40*D40 -> 112
B41: (5)시멘트량 - 심층혼합공법(￠1,000×4rod)
C42: =F36+E38 -> 560 | D42: 3.024 | E42: 250 | F42: 1.03 | G42: 1000 | H42: =ROUND((C42*D42*E42*F42)/G42,2) -> 436.06
...
